Workbook

Sheet Hoja1
B2: COSTA CARIBE ENERO 2024 | G2: BAILARINAS | L2: PLAYA JUNCAL | Q2: BUGA | V2: SAN ANDRES | AA2: CHIQUINQUIRÁ
B3: COSTOS Y GASTOS | G3: COSTOS Y GASTOS | L3: GASTOS Y COSTOS | Q3: costos y gastos | V3: COSTOS Y GASTOS | AA3: COSTOS Y GASTOS
B4: TRANSPORTE | C4: 19600000 | G4: TRANSPORTE | H4: 1900000 | L4: Transporte | M4: 1600000 | Q4: transporte | R4: 4400000 | V4: Tiquetes | W4: 18170700 | AA4: TRANSPORTE | AB4: 2700000
B5: SEGURO | C5: 476000 | G5: SEGURO DE VIAJE | H5: 72000 | L5: ingreso + almuerzo | M5: 778000 | Q5: ingreso + almuerzo | R5: 2680000 | V5: Hospedaje + alimentación | W5: 23301000 | AA5: SEGURO | AB5: 72000
B6: ALOJAMIENTO DESAYUNO RIOHACHA (D) | C6: 2389000 | G6: INGRESO AL PARQUE+ALMUERZO | H6: 2782000 | L6: seguro | M6: 54000 | Q6: seguro | R6: 207000 | V6: Gatos de representación (transporte, tarjeta de Ingreso a la isla, almuerzos, ingresos a atractivos, taxi y bebidas) | W6: 807400 | AA6: ALMUERZO | AB6: 450000
B7: ALOJAMIENTO DESAYUNO RIOHACHA © | C7: 1620000 | G7: TOTAL | H7: 4754000 | L7: refrigerio | M7: 115000 | Q7: total | R7: 7287000 | AA7: MANO DEL ARTESANO | AB7: 240000
B8: AL0JAMIENTO DESAYUNO CENA SANTA MARTA | C8: 15150000 | G8: INGRESO | H8: 5215000 | L8: total | M8: 2547000 | Q8: ingreso | R8: 8370000 | V8: Traslado a playas de rocky cay | W8: 400000 | AA8: GASTOS DE REPRE. | AB8: 50000
B9: PLAN TAGANGA (BUSETA+LANCHA+CARETEO+MANILLA) | C9: 2990000 | G9: UTILIDAD | H9: 461000 | L9: ingresos | M9: 2905000 | Q9: utilidad | R9: 1083000 | V9: Transfer y tours | W9: 3492000 | AA9: TOTAL | AB9: 3512000
L10: utilidad | M10: 358000 | V10: Seguro | W10: 444000 | AA10: INGRESOS | AB10: 3680000
B11: PLAN PLAYA BLANCA (LANCHA+ALMUERZO+MANILLA) | C11: 4550000 | V11: TOTAL | W11: 46615100 | AA11: UTILIDAD | AB11: 168000
Q12: comisionista | R12: pax | S12: comisión | V12: INGRESOS | W12: 53550000
B13: CENA RIOHACHA | C13: 1300000 | G13: COMISIONISTAS | H13: PAX | I13: PAGAR | L13: COMISIONISTAS | M13: PAX | N13: VALOR | Q13: MAFE | R13: 2 | S13: 30000 | V13: UTILIDAD | W13: 6934900
B14: GUÍA TURÍSTICO | C14: 250000 | G14: MAFE | H14: 3 | I14: =H14*15000 -> 45000 | L14: MAFE | M14: 18 | N14: 270000
B15: GASTO DE REPRESENTACIÓN | C15: 300000 | V15: COMISIONES
B16: EVENTO DE GRUPO (MUSICOS, SILLAS, LICOR) | C16: 611000 | V16: MAFE | W16: 4 | X16: 200000
B17: TOTAL | C17: 48625000
B18: INGRESOS | C18: 51850000
B19: UTILIDAD | C19: 3225000 | G19: PARQUE DEL CAFÉ FEBRERO | L19: PARQUE DEL CAFÉ AGOSTO | Q19: MANO GIGANTE | V19: PLAYA HAWAI
G20: Costo y Gastos | L20: COSTOS Y GASTOS | Q20: COSTOS Y GASTOS | V20: COSTOS Y GASTOS
A21: COMISIONISTAS | B21: COMISONADOS | C21: VALOR | D21: TOTAL | G21: Transporte | H21: 1900000 | L21: TRANSPORTE | M21: 2000000 | Q21: TRANSPORTE | R21: 2000000 | V21: TRANSPORTE (BUS Y BUSETA) | W21: 2200000
A22: MAFE | B22: 6 | C22: 50000 | D22: 300000 | G22: Seguro | H22: 78000 | L22: SEGURO | M22: 78000 | Q22: INGRESO A MANO GIGANTE + TRANSPORTE + ALMUERZO | R22: 1788000 | V22: INGRESO+ALMUERZO | W22: 2587000
G23: Ingreso al parque | H23: 2849000 | L23: INGRESO PARQUE | M23: 3003000 | V23: SEGURO | W23: 47000
G24: Almuerzo | H24: 740000 | L24: ALMUERZOS | M24: 722000 | Q24: INGRESO A TERMALES DE RIVERA | R24: 998500 | V24: GASTOS DE REPRESENTACIÓN | W24: 75000
B25: SANTURIO DE LAS LAJAS | G25: Total | H25: 5567000 | L25: GASTOS DE REPRESENTACIÓN | M25: 65000 | Q25: SEGURO | R25: 80000 | V25: INGRESOS EXTRAS | W25: 85000
B26: Gastos y costos | G26: Ingresos | H26: 5912000 | L26: TOTAL | M26: 5868000 | Q26: GASTOS DE REPRESENTACIÓN (DESAYUNOS) | R26: 24000 | V26: TOTAL | W26: 4994000
B27: TRANSPORTE | C27: 7500000 | G27: Utilidad | H27: 345000 | L27: INGRESO | M27: 6505000 | Q27: TOTAL | R27: 4890500 | V27: INGRESOS | W27: 5681000
B28: ALOJAMIENTO 1 + DESAYUNO + CENA | C28: 2117000 | L28: UTILIDAD | M28: 637000 | Q28: INGRESOS | R28: 6350000 | V28: UTILIDAD | W28: 687000
B29: ALOJAMIENTO 2 + DESAYUNO | C29: 1260000 | Q29: UTILIDAD | R29: 1459500
B30: SEGURO | C30: 145000 | G30: COMISIONISTA | H30: PAX | I30: VALOR | V30: COMISIONISTA | W30: PAX | X30: TOTAL
B31: PASEO EN LAGO DE LA COCHA | C31: 300000 | G31: MAFE | H31: 2 | I31: 30000 | Q31: COMISIONISTAS | R31: CANTIDAD | S31: TOTAL | V31: MAFE | W31: 6 | X31: 90000
B32: ALMUERZO EN EL LAGO | C32: 440000 | Q32: MAFE | R32: 4 | S32: 60000
B33: EXCEDENTE ALMUERZO EN EL LAGO | C33: 30000
B34: INGRESO A TERMALES | C34: 665000
B35: GUÍA TURÍSTICO PASTO | C35: 70000 | G35: SANTA ROSA DE CABAL MARZO | L35: SANTA ROSA DE CABAL MAYO | Q35: PRADO | V35: COSTOS Y GASTOS BARRANQUILLA
B36: GUÍA TURÍSTICO POPAYAN | C36: 150000 | D36: almuerzo en tulcan 96800 | G36: COSTOS Y GASTOS | L36: COSTOS Y GASTOS | Q36: COSTOS Y GASTOS | V36: TRANSPORTE | W36: 17500000
B37: GASTOS DE REPRESENTACIÓN (Propina, licor) | C37: 260000 | D37: Almuerzo 43000 | G37: TRANSPORTE | H37: 2100000 | L37: TRANSPORTE | M37: 2100000 | Q37: TRANSPORTE | R37: 6200000 | V37: ALOJAMIENTO | W37: 9120000
B38: ALMUERZOS EMPRESA | C38: 139800 | G38: ALMUERZO | H38: 663000 | L38: INGRESO A TERMALES | M38: 1251000 | Q38: PASEO EN LANCHA + ALMUERZO | R38: 6216000 | V38: DESAYUNOS | W38: 2490000
B39: CENA EN LAJAS | C39: 408000 | G39: INGRESO A TERMALES | H39: 1542600 | L39: SEGURO | M39: 66000 | V39: CENAS | W39: 1944000
B40: INMIGRACIÓN | C40: 200000 | G40: SEGURO | H40: 80000 | L40: ALMUERZO | M40: 528000 | Q40: EVENTO MUSICAL + TRANSPORTE | R40: 500000 | V40: SEGURO | W40: 366000
B41: EXCEDENTE PASTO FRUTA | C41: 42000 | G41: GASTOS DE REPRESENTACIÓN | H41: 122000 | I41: desayuno del sr. Gabriel, wisky | L41: GASTOS DE REPRESENCIÓN (BEBIDAS, SUVENIR) | M41: 120000 | V41: PUNTA ARENA LANCHA + ALMUERZO | W41: 1770000
...

Sheet Hoja2
B2: UTILIDAD DE LOS VIAJES | D2: COMISIONES MAFE | F2: LAS COMISIONES ESTÁN POR FUERA DE LA UTILIDAD | I2: LIQUIDACIÓN DANIELA
B3: COSTA ENERO | C3: =Hoja1!C19 -> 3225000 | D3: =Hoja1!D22 -> 300000 | I3: FECHAS 2024 | J3: PAGO
B4: PLAYA JUNCAL | C4: =Hoja1!M10 -> 358000 | D4: =Hoja1!N14 -> 270000 | I4: 3 ENERO AL 24 ENERO | J4: 360000
B5: BAILARINAS | C5: =Hoja1!H9 -> 461000 | D5: =Hoja1!I14 -> 45000 | I5: 02 FEB AL 27 FEB | J5: 180000
B6: PARQUE DEL CAFÉ 1 | C6: =Hoja1!H27 -> 345000 | D6: =Hoja1!I31 -> 30000 | I6: 29 FEB AL 18 MARZO | J6: 360000
B7: PARQUE DEL CAFÉ 2 | C7: =Hoja1!M28 -> 637000 | D7: 0 | I7: 24 MARZO AL 17 ABRIL | J7: 720000
B8: SANTUARIO DE LAS LAJAS | C8: =Hoja1!C45 -> 2087200 | D8: =Hoja1!D49 -> 80000 | I8: 09 MAYO AL 21 JUNIO | J8: 900000
B9: SANTA ROSA DE CABAL 1 | C9: =Hoja1!H44 -> 1735400 | D9: =Hoja1!I47 -> 60000 | I9: 27 JUNIO AL 6 DE AGOSTO | J9: 480000
B10: SANTA ROSA DE CABAL 2 | C10: =Hoja1!M45 -> 1012000 | D10: =Hoja1!N48 -> 45000 | I10: 28 AGOST AL 04 OCTUBRE | J10: 420000
B11: BUGA | C11: =Hoja1!R9 -> 1083000 | D11: =Hoja1!S13 -> 30000 | I11: TOTAL | J11: =SUM(J4:J10) -> 3420000
B12: MANO GIGANTE | C12: =Hoja1!R29 -> 1459500 | D12: =Hoja1!S32 -> 60000
B13: PRADO | C13: =Hoja1!R50 -> 7101000 | D13: =Hoja1!S53 -> 435000
B14: SAN ANDRES | C14: =Hoja1!W13 -> 6934900 | D14: =Hoja1!X16 -> 200000
B15: PLAYA HAWAI | C15: =Hoja1!W28 -> 687000 | D15: =Hoja1!X31 -> 90000 | F15: UTULIDAD NETA | G15: =C23-C47-J11 -> 23187600 | H15: =G15/2 -> 11593800
B16: BARRANQUILLA | C16: =Hoja1!W48 -> 4747600 | D16: =Hoja1!X52 -> 150000
B17: CHIQUINQUIRÁ | C17: =Hoja1!AB11 -> 168000 | D17: 0
B18: PIEDRA PEÑOL | C18: 869000 | D18: 0
B19: BUGA OCT | C19: 1149000 | D19: 0
B20: PARQUE DEL CAFÉ OCT.
B21: PUNTA CANA
B22: ALUMBRADO NAVIDEÑO
B23: TOTAL | C23: =SUM(C3:C22) -> 34059600 | D23: =SUM(D3:D22) -> 1795000
B25: GASTOS A LÍQUIDAR | C25: VALOR | D25: OBSERVACIONES
B26: CAMARA Y COMERCIO | C26: 328000
B27: RNT | C27: 1120000 | F27: ABONOS A GABRIEL
B28: FONTUR | C28: 12000 | F28: SEGURIDAD SOCIAL GABRIEL | G28: =372000*5 -> 1860000 | H28: MAYO A OCTUBRE
B29: VOLANTES | C29: 290000 | F29: VIAJES SIN PAGOS TOTALES | G29: 300000 | H29: PRADO
B30: PENDON | C30: 160000 | G30: 303000 | H30: PARQUE DEL ARROZ
B31: BUSOS Y GORRAS | C31: 240000 | F31: MATRICULA ISABELLA | G31: 1000000
B32: ARRIENDO | C32: 150000 | D32: ENERO | F32: ABONO SALDO AÑO 2023
C33: =2100000+600000+600000 -> 3300000 | D33: FEB-SEPT ($300.000) | F33: TOTAL | G33: =SUM(G28:G31) -> 3463000
B34: FERIA IBAGUE | C34: 80000 | D34: PEAJES
C35: 170000 | D35: ALMUERZO | G35: % Utilidad grabriel | H35: =H15-G33 -> 8130800
C36: 42000 | D36: DESAYUNOS
C37: 100000 | D37: COMBUSTIBLE
B38: ANATO | C38: 135000 | D38: PASAJE + REFRIGERIO
C39: 180000 | D39: ALMUERO
C40: 50000 | D40: OTROS GASTOS
B41: FERIA TOCAIMA | C41: 180000 | D41: VIATICOS
B42: PUBLICIDAD | C42: 350000 | D42: GUIA TURISTICA
...
